2024-11-25 14:58:25,446 - instabot version: 0.117.0 (bot) - INFO - Instabot version: 0.117.0 Started
2024-11-25 14:58:25,446 - instabot version: 0.117.0 (bot) - DEBUG - Bot imported from C:\Users\griff\anaconda3\Lib\site-packages\instabot\bot\bot.py
2024-11-25 14:58:25,446 - instabot version: 0.117.0 (api_login) - INFO - Not yet logged in starting: PRE-LOGIN FLOW!
2024-11-25 14:58:25,562 - instabot version: 0.117.0 (api) - DEBUG - POST to endpoint: accounts/get_prefill_candidates/ returned response: <Response [429]>
2024-11-25 14:58:25,562 - instabot version: 0.117.0 (api) - DEBUG - Responsecode indicates error; response content: b'{"message":"Please wait a few minutes before you try again.","status":"fail"}'
2024-11-25 14:58:25,567 - instabot version: 0.117.0 (api) - ERROR - Request returns 429 error!
2024-11-25 14:58:25,567 - instabot version: 0.117.0 (api) - WARNING - That means 'too many requests'. I'll go to sleep for 5 minutes.
2024-11-26 13:01:46,279 - instabot version: 0.117.0 (api) - WARNING - HTTPSConnectionPool(host='i.instagram.com', port=443): Max retries exceeded with url: /api/v1/accounts/get_prefill_candidates/ (Caused by NameResolutionError("<urllib3.connection.HTTPSConnection object at 0x00000199912E65A0>: Failed to resolve 'i.instagram.com' ([Errno 11001] getaddrinfo failed)"))
2024-11-26 13:01:46,281 - instabot version: 0.117.0 (api) - WARNING - HTTPSConnectionPool(host='i.instagram.com', port=443): Max retries exceeded with url: /api/v1/qe/sync/ (Caused by NameResolutionError("<urllib3.connection.HTTPSConnection object at 0x00000199913C7590>: Failed to resolve 'i.instagram.com' ([Errno 11001] getaddrinfo failed)"))
2024-11-26 13:01:46,283 - instabot version: 0.117.0 (api) - WARNING - HTTPSConnectionPool(host='i.instagram.com', port=443): Max retries exceeded with url: /api/v1/launcher/sync/ (Caused by NameResolutionError("<urllib3.connection.HTTPSConnection object at 0x00000199913C7A40>: Failed to resolve 'i.instagram.com' ([Errno 11001] getaddrinfo failed)"))
2024-11-26 13:01:46,284 - instabot version: 0.117.0 (api) - WARNING - HTTPSConnectionPool(host='i.instagram.com', port=443): Max retries exceeded with url: /api/v1/accounts/contact_point_prefill/ (Caused by NameResolutionError("<urllib3.connection.HTTPSConnection object at 0x00000199913C7EF0>: Failed to resolve 'i.instagram.com' ([Errno 11001] getaddrinfo failed)"))
